0
Traceback (most recent call last):
  File "/home/sarthak0906/.local/lib/python3.8/site-packages/pandas/core/indexes/base.py", line 2646, in get_loc
    return self._engine.get_loc(key)
  File "pandas/_libs/index.pyx", line 111, in pandas._libs.index.IndexEngine.get_loc
  File "pandas/_libs/index.pyx", line 138, in pandas._libs.index.IndexEngine.get_loc
  File "pandas/_libs/hashtable_class_helper.pxi", line 1619, in pandas._libs.hashtable.PyObjectHashTable.get_item
  File "pandas/_libs/hashtable_class_helper.pxi", line 1627, in pandas._libs.hashtable.PyObjectHashTable.get_item
KeyError: 0

During handling of the above exception, another exception occurred:

Traceback (most recent call last):
  File "../CalculateETFArbitrage/LoadEtfHoldings.py", line 115, in getETFDescriptionfromDB
    return holdingsdatadf[0]
  File "/home/sarthak0906/.local/lib/python3.8/site-packages/pandas/core/frame.py", line 2800, in __getitem__
    indexer = self.columns.get_loc(key)
  File "/home/sarthak0906/.local/lib/python3.8/site-packages/pandas/core/indexes/base.py", line 2648, in get_loc
    return self._engine.get_loc(self._maybe_cast_indexer(key))
  File "pandas/_libs/index.pyx", line 111, in pandas._libs.index.IndexEngine.get_loc
  File "pandas/_libs/index.pyx", line 138, in pandas._libs.index.IndexEngine.get_loc
  File "pandas/_libs/hashtable_class_helper.pxi", line 1619, in pandas._libs.hashtable.PyObjectHashTable.get_item
  File "pandas/_libs/hashtable_class_helper.pxi", line 1627, in pandas._libs.hashtable.PyObjectHashTable.get_item
KeyError: 0
0
Traceback (most recent call last):
  File "/home/sarthak0906/.local/lib/python3.8/site-packages/pandas/core/indexes/base.py", line 2646, in get_loc
    return self._engine.get_loc(key)
  File "pandas/_libs/index.pyx", line 111, in pandas._libs.index.IndexEngine.get_loc
  File "pandas/_libs/index.pyx", line 138, in pandas._libs.index.IndexEngine.get_loc
  File "pandas/_libs/hashtable_class_helper.pxi", line 1619, in pandas._libs.hashtable.PyObjectHashTable.get_item
  File "pandas/_libs/hashtable_class_helper.pxi", line 1627, in pandas._libs.hashtable.PyObjectHashTable.get_item
KeyError: 0

During handling of the above exception, another exception occurred:

Traceback (most recent call last):
  File "../CalculateETFArbitrage/LoadEtfHoldings.py", line 115, in getETFDescriptionfromDB
    return holdingsdatadf[0]
  File "/home/sarthak0906/.local/lib/python3.8/site-packages/pandas/core/frame.py", line 2800, in __getitem__
    indexer = self.columns.get_loc(key)
  File "/home/sarthak0906/.local/lib/python3.8/site-packages/pandas/core/indexes/base.py", line 2648, in get_loc
    return self._engine.get_loc(self._maybe_cast_indexer(key))
  File "pandas/_libs/index.pyx", line 111, in pandas._libs.index.IndexEngine.get_loc
  File "pandas/_libs/index.pyx", line 138, in pandas._libs.index.IndexEngine.get_loc
  File "pandas/_libs/hashtable_class_helper.pxi", line 1619, in pandas._libs.hashtable.PyObjectHashTable.get_item
  File "pandas/_libs/hashtable_class_helper.pxi", line 1627, in pandas._libs.hashtable.PyObjectHashTable.get_item
KeyError: 0
0
Traceback (most recent call last):
  File "/home/sarthak0906/.local/lib/python3.8/site-packages/pandas/core/indexes/base.py", line 2646, in get_loc
    return self._engine.get_loc(key)
  File "pandas/_libs/index.pyx", line 111, in pandas._libs.index.IndexEngine.get_loc
  File "pandas/_libs/index.pyx", line 138, in pandas._libs.index.IndexEngine.get_loc
  File "pandas/_libs/hashtable_class_helper.pxi", line 1619, in pandas._libs.hashtable.PyObjectHashTable.get_item
  File "pandas/_libs/hashtable_class_helper.pxi", line 1627, in pandas._libs.hashtable.PyObjectHashTable.get_item
KeyError: 0

During handling of the above exception, another exception occurred:

Traceback (most recent call last):
  File "../CalculateETFArbitrage/LoadEtfHoldings.py", line 115, in getETFDescriptionfromDB
    return holdingsdatadf[0]
  File "/home/sarthak0906/.local/lib/python3.8/site-packages/pandas/core/frame.py", line 2800, in __getitem__
    indexer = self.columns.get_loc(key)
  File "/home/sarthak0906/.local/lib/python3.8/site-packages/pandas/core/indexes/base.py", line 2648, in get_loc
    return self._engine.get_loc(self._maybe_cast_indexer(key))
  File "pandas/_libs/index.pyx", line 111, in pandas._libs.index.IndexEngine.get_loc
  File "pandas/_libs/index.pyx", line 138, in pandas._libs.index.IndexEngine.get_loc
  File "pandas/_libs/hashtable_class_helper.pxi", line 1619, in pandas._libs.hashtable.PyObjectHashTable.get_item
  File "pandas/_libs/hashtable_class_helper.pxi", line 1627, in pandas._libs.hashtable.PyObjectHashTable.get_item
KeyError: 0
0
Traceback (most recent call last):
  File "/home/sarthak0906/.local/lib/python3.8/site-packages/pandas/core/indexes/base.py", line 2646, in get_loc
    return self._engine.get_loc(key)
  File "pandas/_libs/index.pyx", line 111, in pandas._libs.index.IndexEngine.get_loc
  File "pandas/_libs/index.pyx", line 138, in pandas._libs.index.IndexEngine.get_loc
  File "pandas/_libs/hashtable_class_helper.pxi", line 1619, in pandas._libs.hashtable.PyObjectHashTable.get_item
  File "pandas/_libs/hashtable_class_helper.pxi", line 1627, in pandas._libs.hashtable.PyObjectHashTable.get_item
KeyError: 0

During handling of the above exception, another exception occurred:

Traceback (most recent call last):
  File "../CalculateETFArbitrage/LoadEtfHoldings.py", line 115, in getETFDescriptionfromDB
    return holdingsdatadf[0]
  File "/home/sarthak0906/.local/lib/python3.8/site-packages/pandas/core/frame.py", line 2800, in __getitem__
    indexer = self.columns.get_loc(key)
  File "/home/sarthak0906/.local/lib/python3.8/site-packages/pandas/core/indexes/base.py", line 2648, in get_loc
    return self._engine.get_loc(self._maybe_cast_indexer(key))
  File "pandas/_libs/index.pyx", line 111, in pandas._libs.index.IndexEngine.get_loc
  File "pandas/_libs/index.pyx", line 138, in pandas._libs.index.IndexEngine.get_loc
  File "pandas/_libs/hashtable_class_helper.pxi", line 1619, in pandas._libs.hashtable.PyObjectHashTable.get_item
  File "pandas/_libs/hashtable_class_helper.pxi", line 1627, in pandas._libs.hashtable.PyObjectHashTable.get_item
KeyError: 0
0
Traceback (most recent call last):
  File "/home/sarthak0906/.local/lib/python3.8/site-packages/pandas/core/indexes/base.py", line 2646, in get_loc
    return self._engine.get_loc(key)
  File "pandas/_libs/index.pyx", line 111, in pandas._libs.index.IndexEngine.get_loc
  File "pandas/_libs/index.pyx", line 138, in pandas._libs.index.IndexEngine.get_loc
  File "pandas/_libs/hashtable_class_helper.pxi", line 1619, in pandas._libs.hashtable.PyObjectHashTable.get_item
  File "pandas/_libs/hashtable_class_helper.pxi", line 1627, in pandas._libs.hashtable.PyObjectHashTable.get_item
KeyError: 0

During handling of the above exception, another exception occurred:

Traceback (most recent call last):
  File "../CalculateETFArbitrage/LoadEtfHoldings.py", line 115, in getETFDescriptionfromDB
    return holdingsdatadf[0]
  File "/home/sarthak0906/.local/lib/python3.8/site-packages/pandas/core/frame.py", line 2800, in __getitem__
    indexer = self.columns.get_loc(key)
  File "/home/sarthak0906/.local/lib/python3.8/site-packages/pandas/core/indexes/base.py", line 2648, in get_loc
    return self._engine.get_loc(self._maybe_cast_indexer(key))
  File "pandas/_libs/index.pyx", line 111, in pandas._libs.index.IndexEngine.get_loc
  File "pandas/_libs/index.pyx", line 138, in pandas._libs.index.IndexEngine.get_loc
  File "pandas/_libs/hashtable_class_helper.pxi", line 1619, in pandas._libs.hashtable.PyObjectHashTable.get_item
  File "pandas/_libs/hashtable_class_helper.pxi", line 1627, in pandas._libs.hashtable.PyObjectHashTable.get_item
KeyError: 0
0
Traceback (most recent call last):
  File "/home/sarthak0906/.local/lib/python3.8/site-packages/pandas/core/indexes/base.py", line 2646, in get_loc
    return self._engine.get_loc(key)
  File "pandas/_libs/index.pyx", line 111, in pandas._libs.index.IndexEngine.get_loc
  File "pandas/_libs/index.pyx", line 138, in pandas._libs.index.IndexEngine.get_loc
  File "pandas/_libs/hashtable_class_helper.pxi", line 1619, in pandas._libs.hashtable.PyObjectHashTable.get_item
  File "pandas/_libs/hashtable_class_helper.pxi", line 1627, in pandas._libs.hashtable.PyObjectHashTable.get_item
KeyError: 0

During handling of the above exception, another exception occurred:

Traceback (most recent call last):
  File "../CalculateETFArbitrage/LoadEtfHoldings.py", line 115, in getETFDescriptionfromDB
    return holdingsdatadf[0]
  File "/home/sarthak0906/.local/lib/python3.8/site-packages/pandas/core/frame.py", line 2800, in __getitem__
    indexer = self.columns.get_loc(key)
  File "/home/sarthak0906/.local/lib/python3.8/site-packages/pandas/core/indexes/base.py", line 2648, in get_loc
    return self._engine.get_loc(self._maybe_cast_indexer(key))
  File "pandas/_libs/index.pyx", line 111, in pandas._libs.index.IndexEngine.get_loc
  File "pandas/_libs/index.pyx", line 138, in pandas._libs.index.IndexEngine.get_loc
  File "pandas/_libs/hashtable_class_helper.pxi", line 1619, in pandas._libs.hashtable.PyObjectHashTable.get_item
  File "pandas/_libs/hashtable_class_helper.pxi", line 1627, in pandas._libs.hashtable.PyObjectHashTable.get_item
KeyError: 0
0
Traceback (most recent call last):
  File "/home/sarthak0906/.local/lib/python3.8/site-packages/pandas/core/indexes/base.py", line 2646, in get_loc
    return self._engine.get_loc(key)
  File "pandas/_libs/index.pyx", line 111, in pandas._libs.index.IndexEngine.get_loc
  File "pandas/_libs/index.pyx", line 138, in pandas._libs.index.IndexEngine.get_loc
  File "pandas/_libs/hashtable_class_helper.pxi", line 1619, in pandas._libs.hashtable.PyObjectHashTable.get_item
  File "pandas/_libs/hashtable_class_helper.pxi", line 1627, in pandas._libs.hashtable.PyObjectHashTable.get_item
KeyError: 0

During handling of the above exception, another exception occurred:

Traceback (most recent call last):
  File "../CalculateETFArbitrage/LoadEtfHoldings.py", line 115, in getETFDescriptionfromDB
    return holdingsdatadf[0]
  File "/home/sarthak0906/.local/lib/python3.8/site-packages/pandas/core/frame.py", line 2800, in __getitem__
    indexer = self.columns.get_loc(key)
  File "/home/sarthak0906/.local/lib/python3.8/site-packages/pandas/core/indexes/base.py", line 2648, in get_loc
    return self._engine.get_loc(self._maybe_cast_indexer(key))
  File "pandas/_libs/index.pyx", line 111, in pandas._libs.index.IndexEngine.get_loc
  File "pandas/_libs/index.pyx", line 138, in pandas._libs.index.IndexEngine.get_loc
  File "pandas/_libs/hashtable_class_helper.pxi", line 1619, in pandas._libs.hashtable.PyObjectHashTable.get_item
  File "pandas/_libs/hashtable_class_helper.pxi", line 1627, in pandas._libs.hashtable.PyObjectHashTable.get_item
KeyError: 0
0
Traceback (most recent call last):
  File "/home/sarthak0906/.local/lib/python3.8/site-packages/pandas/core/indexes/base.py", line 2646, in get_loc
    return self._engine.get_loc(key)
  File "pandas/_libs/index.pyx", line 111, in pandas._libs.index.IndexEngine.get_loc
  File "pandas/_libs/index.pyx", line 138, in pandas._libs.index.IndexEngine.get_loc
  File "pandas/_libs/hashtable_class_helper.pxi", line 1619, in pandas._libs.hashtable.PyObjectHashTable.get_item
  File "pandas/_libs/hashtable_class_helper.pxi", line 1627, in pandas._libs.hashtable.PyObjectHashTable.get_item
KeyError: 0

During handling of the above exception, another exception occurred:

Traceback (most recent call last):
  File "../CalculateETFArbitrage/LoadEtfHoldings.py", line 115, in getETFDescriptionfromDB
    return holdingsdatadf[0]
  File "/home/sarthak0906/.local/lib/python3.8/site-packages/pandas/core/frame.py", line 2800, in __getitem__
    indexer = self.columns.get_loc(key)
  File "/home/sarthak0906/.local/lib/python3.8/site-packages/pandas/core/indexes/base.py", line 2648, in get_loc
    return self._engine.get_loc(self._maybe_cast_indexer(key))
  File "pandas/_libs/index.pyx", line 111, in pandas._libs.index.IndexEngine.get_loc
  File "pandas/_libs/index.pyx", line 138, in pandas._libs.index.IndexEngine.get_loc
  File "pandas/_libs/hashtable_class_helper.pxi", line 1619, in pandas._libs.hashtable.PyObjectHashTable.get_item
  File "pandas/_libs/hashtable_class_helper.pxi", line 1627, in pandas._libs.hashtable.PyObjectHashTable.get_item
KeyError: 0
0
Traceback (most recent call last):
  File "/home/sarthak0906/.local/lib/python3.8/site-packages/pandas/core/indexes/base.py", line 2646, in get_loc
    return self._engine.get_loc(key)
  File "pandas/_libs/index.pyx", line 111, in pandas._libs.index.IndexEngine.get_loc
  File "pandas/_libs/index.pyx", line 138, in pandas._libs.index.IndexEngine.get_loc
  File "pandas/_libs/hashtable_class_helper.pxi", line 1619, in pandas._libs.hashtable.PyObjectHashTable.get_item
  File "pandas/_libs/hashtable_class_helper.pxi", line 1627, in pandas._libs.hashtable.PyObjectHashTable.get_item
KeyError: 0

During handling of the above exception, another exception occurred:

Traceback (most recent call last):
  File "../CalculateETFArbitrage/LoadEtfHoldings.py", line 115, in getETFDescriptionfromDB
    return holdingsdatadf[0]
  File "/home/sarthak0906/.local/lib/python3.8/site-packages/pandas/core/frame.py", line 2800, in __getitem__
    indexer = self.columns.get_loc(key)
  File "/home/sarthak0906/.local/lib/python3.8/site-packages/pandas/core/indexes/base.py", line 2648, in get_loc
    return self._engine.get_loc(self._maybe_cast_indexer(key))
  File "pandas/_libs/index.pyx", line 111, in pandas._libs.index.IndexEngine.get_loc
  File "pandas/_libs/index.pyx", line 138, in pandas._libs.index.IndexEngine.get_loc
  File "pandas/_libs/hashtable_class_helper.pxi", line 1619, in pandas._libs.hashtable.PyObjectHashTable.get_item
  File "pandas/_libs/hashtable_class_helper.pxi", line 1627, in pandas._libs.hashtable.PyObjectHashTable.get_item
KeyError: 0
0
Traceback (most recent call last):
  File "/home/sarthak0906/.local/lib/python3.8/site-packages/pandas/core/indexes/base.py", line 2646, in get_loc
    return self._engine.get_loc(key)
  File "pandas/_libs/index.pyx", line 111, in pandas._libs.index.IndexEngine.get_loc
  File "pandas/_libs/index.pyx", line 138, in pandas._libs.index.IndexEngine.get_loc
  File "pandas/_libs/hashtable_class_helper.pxi", line 1619, in pandas._libs.hashtable.PyObjectHashTable.get_item
  File "pandas/_libs/hashtable_class_helper.pxi", line 1627, in pandas._libs.hashtable.PyObjectHashTable.get_item
KeyError: 0

During handling of the above exception, another exception occurred:

Traceback (most recent call last):
  File "../CalculateETFArbitrage/LoadEtfHoldings.py", line 115, in getETFDescriptionfromDB
    print(holdingsdatadf[0])
  File "/home/sarthak0906/.local/lib/python3.8/site-packages/pandas/core/frame.py", line 2800, in __getitem__
    indexer = self.columns.get_loc(key)
  File "/home/sarthak0906/.local/lib/python3.8/site-packages/pandas/core/indexes/base.py", line 2648, in get_loc
    return self._engine.get_loc(self._maybe_cast_indexer(key))
  File "pandas/_libs/index.pyx", line 111, in pandas._libs.index.IndexEngine.get_loc
  File "pandas/_libs/index.pyx", line 138, in pandas._libs.index.IndexEngine.get_loc
  File "pandas/_libs/hashtable_class_helper.pxi", line 1619, in pandas._libs.hashtable.PyObjectHashTable.get_item
  File "pandas/_libs/hashtable_class_helper.pxi", line 1627, in pandas._libs.hashtable.PyObjectHashTable.get_item
KeyError: 0
'DataFrame' object has no attribute 'to_list'
Traceback (most recent call last):
  File "../CalculateETFArbitrage/LoadEtfHoldings.py", line 110, in getETFDescriptionfromDB
    holdingsdatadf = pd.DataFrame(etfdata.to_mongo().to_dict()).to_list()
  File "/home/sarthak0906/.local/lib/python3.8/site-packages/pandas/core/generic.py", line 5274, in __getattr__
    return object.__getattribute__(self, name)
AttributeError: 'DataFrame' object has no attribute 'to_list'
'numpy.ndarray' object has no attribute 'to_list'
Traceback (most recent call last):
  File "../CalculateETFArbitrage/LoadEtfHoldings.py", line 110, in getETFDescriptionfromDB
    holdingsdatadf = pd.DataFrame(etfdata.to_mongo().to_dict()).values.to_list()
AttributeError: 'numpy.ndarray' object has no attribute 'to_list'
list indices must be integers or slices, not str
Traceback (most recent call last):
  File "../CalculateETFArbitrage/LoadEtfHoldings.py", line 111, in getETFDescriptionfromDB
    del holdingsdatadf['holdings']
TypeError: list indices must be integers or slices, not str
cannot delete array elements
Traceback (most recent call last):
  File "../CalculateETFArbitrage/LoadEtfHoldings.py", line 111, in getETFDescriptionfromDB
    del holdingsdatadf['holdings']
ValueError: cannot delete array elements
cannot delete array elements
Traceback (most recent call last):
  File "../CalculateETFArbitrage/LoadEtfHoldings.py", line 111, in getETFDescriptionfromDB
    del holdingsdatadf['holdings']
ValueError: cannot delete array elements
cannot delete array elements
Traceback (most recent call last):
  File "../CalculateETFArbitrage/LoadEtfHoldings.py", line 111, in getETFDescriptionfromDB
    del holdingsdatadf['holdings']
ValueError: cannot delete array elements
cannot delete array elements
Traceback (most recent call last):
  File "../CalculateETFArbitrage/LoadEtfHoldings.py", line 111, in getETFDescriptionfromDB
    del holdingsdatadf['holdings']
ValueError: cannot delete array elements
cannot delete array elements
Traceback (most recent call last):
  File "../CalculateETFArbitrage/LoadEtfHoldings.py", line 111, in getETFDescriptionfromDB
    del holdingsdatadf['holdings']
ValueError: cannot delete array elements
cannot delete array elements
Traceback (most recent call last):
  File "../CalculateETFArbitrage/LoadEtfHoldings.py", line 111, in getETFDescriptionfromDB
    del holdingsdatadf['holdings']
ValueError: cannot delete array elements
cannot delete array elements
Traceback (most recent call last):
  File "../CalculateETFArbitrage/LoadEtfHoldings.py", line 111, in getETFDescriptionfromDB
    del holdingsdatadf['holdings']
ValueError: cannot delete array elements
cannot delete array elements
Traceback (most recent call last):
  File "../CalculateETFArbitrage/LoadEtfHoldings.py", line 111, in getETFDescriptionfromDB
    del holdingsdatadf['holdings']
ValueError: cannot delete array elements
cannot delete array elements
Traceback (most recent call last):
  File "../CalculateETFArbitrage/LoadEtfHoldings.py", line 111, in getETFDescriptionfromDB
    del holdingsdatadf['holdings']
ValueError: cannot delete array elements
cannot delete array elements
Traceback (most recent call last):
  File "../CalculateETFArbitrage/LoadEtfHoldings.py", line 111, in getETFDescriptionfromDB
    del holdingsdatadf['holdings']
ValueError: cannot delete array elements
'dict' object has no attribute 'tolist'
Traceback (most recent call last):
  File "../CalculateETFArbitrage/LoadEtfHoldings.py", line 111, in getETFDescriptionfromDB
    holdingsdatadf = pd.DataFrame(etfdata.to_mongo().to_dict().tolist())
AttributeError: 'dict' object has no attribute 'tolist'
'utf-8' codec can't decode byte 0xac in position 48: invalid start byte
Traceback (most recent call last):
  File "../CalculateETFArbitrage/LoadEtfHoldings.py", line 114, in getETFDescriptionfromDB
    return holdingsdatadf.to_json()
  File "/home/sarthak0906/.local/lib/python3.8/site-packages/pandas/core/generic.py", line 2352, in to_json
    return json.to_json(
  File "/home/sarthak0906/.local/lib/python3.8/site-packages/pandas/io/json/_json.py", line 76, in to_json
    s = writer(
  File "/home/sarthak0906/.local/lib/python3.8/site-packages/pandas/io/json/_json.py", line 137, in write
    return self._write(
  File "/home/sarthak0906/.local/lib/python3.8/site-packages/pandas/io/json/_json.py", line 237, in _write
    return super()._write(
  File "/home/sarthak0906/.local/lib/python3.8/site-packages/pandas/io/json/_json.py", line 159, in _write
    return dumps(
UnicodeDecodeError: 'utf-8' codec can't decode byte 0xac in position 48: invalid start byte
'ObjectId'
Traceback (most recent call last):
  File "/home/sarthak0906/.local/lib/python3.8/site-packages/pandas/core/indexes/base.py", line 2646, in get_loc
    return self._engine.get_loc(key)
  File "pandas/_libs/index.pyx", line 111, in pandas._libs.index.IndexEngine.get_loc
  File "pandas/_libs/index.pyx", line 138, in pandas._libs.index.IndexEngine.get_loc
  File "pandas/_libs/hashtable_class_helper.pxi", line 1619, in pandas._libs.hashtable.PyObjectHashTable.get_item
  File "pandas/_libs/hashtable_class_helper.pxi", line 1627, in pandas._libs.hashtable.PyObjectHashTable.get_item
KeyError: 'ObjectId'

During handling of the above exception, another exception occurred:

Traceback (most recent call last):
  File "../CalculateETFArbitrage/LoadEtfHoldings.py", line 112, in getETFDescriptionfromDB
    del holdingsdatadf['ObjectId']
  File "/home/sarthak0906/.local/lib/python3.8/site-packages/pandas/core/generic.py", line 3759, in __delitem__
    self._data.delete(key)
  File "/home/sarthak0906/.local/lib/python3.8/site-packages/pandas/core/internals/managers.py", line 1002, in delete
    indexer = self.items.get_loc(item)
  File "/home/sarthak0906/.local/lib/python3.8/site-packages/pandas/core/indexes/base.py", line 2648, in get_loc
    return self._engine.get_loc(self._maybe_cast_indexer(key))
  File "pandas/_libs/index.pyx", line 111, in pandas._libs.index.IndexEngine.get_loc
  File "pandas/_libs/index.pyx", line 138, in pandas._libs.index.IndexEngine.get_loc
  File "pandas/_libs/hashtable_class_helper.pxi", line 1619, in pandas._libs.hashtable.PyObjectHashTable.get_item
  File "pandas/_libs/hashtable_class_helper.pxi", line 1627, in pandas._libs.hashtable.PyObjectHashTable.get_item
KeyError: 'ObjectId'
'ObjectId'
Traceback (most recent call last):
  File "/home/sarthak0906/.local/lib/python3.8/site-packages/pandas/core/indexes/base.py", line 2646, in get_loc
    return self._engine.get_loc(key)
  File "pandas/_libs/index.pyx", line 111, in pandas._libs.index.IndexEngine.get_loc
  File "pandas/_libs/index.pyx", line 138, in pandas._libs.index.IndexEngine.get_loc
  File "pandas/_libs/hashtable_class_helper.pxi", line 1619, in pandas._libs.hashtable.PyObjectHashTable.get_item
  File "pandas/_libs/hashtable_class_helper.pxi", line 1627, in pandas._libs.hashtable.PyObjectHashTable.get_item
KeyError: 'ObjectId'

During handling of the above exception, another exception occurred:

Traceback (most recent call last):
  File "../CalculateETFArbitrage/LoadEtfHoldings.py", line 112, in getETFDescriptionfromDB
    del holdingsdatadf['ObjectId']
  File "/home/sarthak0906/.local/lib/python3.8/site-packages/pandas/core/generic.py", line 3759, in __delitem__
    self._data.delete(key)
  File "/home/sarthak0906/.local/lib/python3.8/site-packages/pandas/core/internals/managers.py", line 1002, in delete
    indexer = self.items.get_loc(item)
  File "/home/sarthak0906/.local/lib/python3.8/site-packages/pandas/core/indexes/base.py", line 2648, in get_loc
    return self._engine.get_loc(self._maybe_cast_indexer(key))
  File "pandas/_libs/index.pyx", line 111, in pandas._libs.index.IndexEngine.get_loc
  File "pandas/_libs/index.pyx", line 138, in pandas._libs.index.IndexEngine.get_loc
  File "pandas/_libs/hashtable_class_helper.pxi", line 1619, in pandas._libs.hashtable.PyObjectHashTable.get_item
  File "pandas/_libs/hashtable_class_helper.pxi", line 1627, in pandas._libs.hashtable.PyObjectHashTable.get_item
KeyError: 'ObjectId'
'ObjectId'
Traceback (most recent call last):
  File "../CalculateETFArbitrage/LoadEtfHoldings.py", line 111, in getETFDescriptionfromDB
    holdingsdatadf = pd.DataFrame(etfdata.to_mongo().to_dict()['ObjectId'])
KeyError: 'ObjectId'
'ObjectId'
Traceback (most recent call last):
  File "../CalculateETFArbitrage/LoadEtfHoldings.py", line 111, in getETFDescriptionfromDB
    holdingsdatadf = pd.DataFrame(etfdata.to_mongo().to_dict()['ObjectId'])
KeyError: 'ObjectId'
0
Traceback (most recent call last):
  File "/home/sarthak0906/.local/lib/python3.8/site-packages/pandas/core/indexes/base.py", line 2646, in get_loc
    return self._engine.get_loc(key)
  File "pandas/_libs/index.pyx", line 111, in pandas._libs.index.IndexEngine.get_loc
  File "pandas/_libs/index.pyx", line 138, in pandas._libs.index.IndexEngine.get_loc
  File "pandas/_libs/hashtable_class_helper.pxi", line 1619, in pandas._libs.hashtable.PyObjectHashTable.get_item
  File "pandas/_libs/hashtable_class_helper.pxi", line 1627, in pandas._libs.hashtable.PyObjectHashTable.get_item
KeyError: 0

During handling of the above exception, another exception occurred:

Traceback (most recent call last):
  File "../CalculateETFArbitrage/LoadEtfHoldings.py", line 116, in getETFDescriptionfromDB
    return holdingsdatadf[0]
  File "/home/sarthak0906/.local/lib/python3.8/site-packages/pandas/core/frame.py", line 2800, in __getitem__
    indexer = self.columns.get_loc(key)
  File "/home/sarthak0906/.local/lib/python3.8/site-packages/pandas/core/indexes/base.py", line 2648, in get_loc
    return self._engine.get_loc(self._maybe_cast_indexer(key))
  File "pandas/_libs/index.pyx", line 111, in pandas._libs.index.IndexEngine.get_loc
  File "pandas/_libs/index.pyx", line 138, in pandas._libs.index.IndexEngine.get_loc
  File "pandas/_libs/hashtable_class_helper.pxi", line 1619, in pandas._libs.hashtable.PyObjectHashTable.get_item
  File "pandas/_libs/hashtable_class_helper.pxi", line 1627, in pandas._libs.hashtable.PyObjectHashTable.get_item
KeyError: 0
'0'
Traceback (most recent call last):
  File "/home/sarthak0906/.local/lib/python3.8/site-packages/pandas/core/indexes/base.py", line 2646, in get_loc
    return self._engine.get_loc(key)
  File "pandas/_libs/index.pyx", line 111, in pandas._libs.index.IndexEngine.get_loc
  File "pandas/_libs/index.pyx", line 138, in pandas._libs.index.IndexEngine.get_loc
  File "pandas/_libs/hashtable_class_helper.pxi", line 1619, in pandas._libs.hashtable.PyObjectHashTable.get_item
  File "pandas/_libs/hashtable_class_helper.pxi", line 1627, in pandas._libs.hashtable.PyObjectHashTable.get_item
KeyError: '0'

During handling of the above exception, another exception occurred:

Traceback (most recent call last):
  File "../CalculateETFArbitrage/LoadEtfHoldings.py", line 116, in getETFDescriptionfromDB
    return holdingsdatadf["0"]
  File "/home/sarthak0906/.local/lib/python3.8/site-packages/pandas/core/frame.py", line 2800, in __getitem__
    indexer = self.columns.get_loc(key)
  File "/home/sarthak0906/.local/lib/python3.8/site-packages/pandas/core/indexes/base.py", line 2648, in get_loc
    return self._engine.get_loc(self._maybe_cast_indexer(key))
  File "pandas/_libs/index.pyx", line 111, in pandas._libs.index.IndexEngine.get_loc
  File "pandas/_libs/index.pyx", line 138, in pandas._libs.index.IndexEngine.get_loc
  File "pandas/_libs/hashtable_class_helper.pxi", line 1619, in pandas._libs.hashtable.PyObjectHashTable.get_item
  File "pandas/_libs/hashtable_class_helper.pxi", line 1627, in pandas._libs.hashtable.PyObjectHashTable.get_item
KeyError: '0'
'NoneType' object has no attribute 'to_mongo'
Traceback (most recent call last):
  File "../CalculateETFArbitrage/LoadEtfHoldings.py", line 111, in getETFDescriptionfromDB
    holdingsdatadf = pd.DataFrame(etfdata.to_mongo().to_dict())
AttributeError: 'NoneType' object has no attribute 'to_mongo'
'NoneType' object has no attribute 'to_mongo'
Traceback (most recent call last):
  File "../CalculateETFArbitrage/LoadEtfHoldings.py", line 86, in getHoldingsDatafromDB
    holdingsdatadf = pd.DataFrame(etfdata.to_mongo().to_dict()['holdings'])
AttributeError: 'NoneType' object has no attribute 'to_mongo'
'ETF_db'
Traceback (most recent call last):
  File "../CalculateETFArbitrage/LoadEtfHoldings.py", line 88, in getHoldingsDatafromDB
    disconnect('ETF_db')
  File "/home/sarthak0906/.local/lib/python3.8/site-packages/mongoengine/connection.py", line 229, in disconnect
    del _connections[alias]
KeyError: 'ETF_db'
'ETF_db'
Traceback (most recent call last):
  File "../CalculateETFArbitrage/LoadEtfHoldings.py", line 107, in getAllETFData
    disconnect('ETF_db')
  File "/Users/kshitizsharma/miniconda3/lib/python3.6/site-packages/mongoengine/connection.py", line 230, in disconnect
    del _connections[alias]
KeyError: 'ETF_db'
'NoneType' object has no attribute 'find'
Traceback (most recent call last):
  File "../CalculateETFArbitrage/LoadEtfHoldings.py", line 106, in getAllETFData
    '-FundHoldingsDate').first()
  File "/Users/kshitizsharma/miniconda3/lib/python3.6/site-packages/mongoengine/queryset/base.py", line 285, in first
    result = queryset[0]
  File "/Users/kshitizsharma/miniconda3/lib/python3.6/site-packages/mongoengine/queryset/base.py", line 188, in __getitem__
    queryset._cursor[key],
  File "/Users/kshitizsharma/miniconda3/lib/python3.6/site-packages/mongoengine/queryset/base.py", line 1650, in _cursor
    self._cursor_obj = self._collection.find(self._query, **self._cursor_args)
AttributeError: 'NoneType' object has no attribute 'find'
'ETF_db'
Traceback (most recent call last):
  File "../CalculateETFArbitrage/LoadEtfHoldings.py", line 107, in getAllETFData
    disconnect('ETF_db')
  File "/Users/kshitizsharma/miniconda3/lib/python3.6/site-packages/mongoengine/connection.py", line 230, in disconnect
    del _connections[alias]
KeyError: 'ETF_db'
'NoneType' object has no attribute 'find'
Traceback (most recent call last):
  File "../CalculateETFArbitrage/LoadEtfHoldings.py", line 106, in getAllETFData
    '-FundHoldingsDate').first()
  File "/Users/kshitizsharma/miniconda3/lib/python3.6/site-packages/mongoengine/queryset/base.py", line 285, in first
    result = queryset[0]
  File "/Users/kshitizsharma/miniconda3/lib/python3.6/site-packages/mongoengine/queryset/base.py", line 188, in __getitem__
    queryset._cursor[key],
  File "/Users/kshitizsharma/miniconda3/lib/python3.6/site-packages/mongoengine/queryset/base.py", line 1650, in _cursor
    self._cursor_obj = self._collection.find(self._query, **self._cursor_args)
AttributeError: 'NoneType' object has no attribute 'find'
'ETF_db'
Traceback (most recent call last):
  File "../CalculateETFArbitrage/LoadEtfHoldings.py", line 107, in getAllETFData
    disconnect('ETF_db')
  File "/Users/kshitizsharma/miniconda3/lib/python3.6/site-packages/mongoengine/connection.py", line 230, in disconnect
    del _connections[alias]
KeyError: 'ETF_db'
'NoneType' object has no attribute 'find'
Traceback (most recent call last):
  File "../CalculateETFArbitrage/LoadEtfHoldings.py", line 106, in getAllETFData
    '-FundHoldingsDate').first()
  File "/Users/kshitizsharma/miniconda3/lib/python3.6/site-packages/mongoengine/queryset/base.py", line 285, in first
    result = queryset[0]
  File "/Users/kshitizsharma/miniconda3/lib/python3.6/site-packages/mongoengine/queryset/base.py", line 188, in __getitem__
    queryset._cursor[key],
  File "/Users/kshitizsharma/miniconda3/lib/python3.6/site-packages/mongoengine/queryset/base.py", line 1650, in _cursor
    self._cursor_obj = self._collection.find(self._query, **self._cursor_args)
AttributeError: 'NoneType' object has no attribute 'find'
'ETF_db'
Traceback (most recent call last):
  File "../CalculateETFArbitrage/LoadEtfHoldings.py", line 107, in getAllETFData
    disconnect('ETF_db')
  File "/Users/kshitizsharma/miniconda3/lib/python3.6/site-packages/mongoengine/connection.py", line 230, in disconnect
    del _connections[alias]
KeyError: 'ETF_db'
'NoneType' object has no attribute 'find'
Traceback (most recent call last):
  File "../CalculateETFArbitrage/LoadEtfHoldings.py", line 106, in getAllETFData
    '-FundHoldingsDate').first()
  File "/Users/kshitizsharma/miniconda3/lib/python3.6/site-packages/mongoengine/queryset/base.py", line 285, in first
    result = queryset[0]
  File "/Users/kshitizsharma/miniconda3/lib/python3.6/site-packages/mongoengine/queryset/base.py", line 188, in __getitem__
    queryset._cursor[key],
  File "/Users/kshitizsharma/miniconda3/lib/python3.6/site-packages/mongoengine/queryset/base.py", line 1650, in _cursor
    self._cursor_obj = self._collection.find(self._query, **self._cursor_args)
AttributeError: 'NoneType' object has no attribute 'find'
'ETF_db'
Traceback (most recent call last):
  File "../CalculateETFArbitrage/LoadEtfHoldings.py", line 107, in getAllETFData
    disconnect('ETF_db')
  File "/Users/kshitizsharma/miniconda3/lib/python3.6/site-packages/mongoengine/connection.py", line 230, in disconnect
    del _connections[alias]
KeyError: 'ETF_db'
